{
  "_content": {
    "Attributes": {
      "children": [],
      "title": null
    },
    "Extended Summary": {
      "children": [
        {
          "type": "Paragraph",
          "data": {
            "inline": [
              {
                "type": "Words",
                "data": {
                  "value": "This may be called multiple times by Python 3 exception chaining (PEP 3134)."
                }
              }
            ],
            "inner": []
          }
        }
      ],
      "title": null
    },
    "Methods": {
      "children": [],
      "title": null
    },
    "Notes": {
      "children": [],
      "title": null
    },
    "Other Parameters": {
      "children": [],
      "title": null
    },
    "Parameters": {
      "children": [],
      "title": null
    },
    "Raises": {
      "children": [],
      "title": null
    },
    "Receives": {
      "children": [],
      "title": null
    },
    "Returns": {
      "children": [],
      "title": null
    },
    "Summary": {
      "children": [
        {
          "type": "Paragraph",
          "data": {
            "inline": [
              {
                "type": "Words",
                "data": {
                  "value": "Formats the header, traceback and exception message for a single exception."
                }
              }
            ],
            "inner": []
          }
        }
      ],
      "title": null
    },
    "Warnings": {
      "children": [],
      "title": null
    },
    "Warns": {
      "children": [],
      "title": null
    },
    "Yields": {
      "children": [],
      "title": null
    }
  },
  "refs": [],
  "ordered_sections": [
    "Summary",
    "Extended Summary"
  ],
  "item_file": "/dev/ipython/IPython/core/ultratb.py",
  "item_line": 728,
  "item_type": "<class 'function'>",
  "aliases": [
    "IPython.core.ultratb.VerboseTB.format_exception_as_a_whole"
  ],
  "example_section_data": {
    "children": [],
    "title": null
  },
  "see_also": [],
  "version": "8.0.0.dev",
  "signature": "format_exception_as_a_whole(self, etype, evalue, etb, number_of_lines_of_context, tb_offset)",
  "references": null,
  "logo": "logo.png",
  "qa": "IPython.core.ultratb.VerboseTB.format_exception_as_a_whole",
  "arbitrary": []
}